{"trial_id": "01", "hyperparameters": {"space": [{"class_name": "Int", "config": {"name": "units", "default": null, "conditions": [], "min_value": 512, "max_value": 2048, "step": 256, "sampling": "linear"}}, {"class_name": "Float", "config": {"name": "dropout", "default": 0.1, "conditions": [], "min_value": 0.1, "max_value": 0.5, "step": 0.1, "sampling": "linear"}}, {"class_name": "Float", "config": {"name": "learning_rate", "default": 1e-05, "conditions": [], "min_value": 1e-05, "max_value": 0.01, "step": null, "sampling": "log"}}], "values": {"units": 1536, "dropout": 0.1, "learning_rate": 0.0019671144721368837}}, "metrics": {"metrics": {}}, "score": null, "best_step": 0, "status": "FAILED", "message": "Traceback (most recent call last):\n  File \"/Users/aadityasurya/anaconda3/lib/python3.11/site-packages/keras_tuner/engine/base_tuner.py\", line 270, in _try_run_and_update_trial\n    self._run_and_update_trial(trial, *fit_args, **fit_kwargs)\n  File \"/Users/aadityasurya/anaconda3/lib/python3.11/site-packages/keras_tuner/engine/base_tuner.py\", line 235, in _run_and_update_trial\n    results = self.run_trial(trial, *fit_args, **fit_kwargs)\n              ^^^^^^^^^^^^^^^^^^^^^^^^^^^^^^^^^^^^^^^^^^^^^^\n  File \"/Users/aadityasurya/anaconda3/lib/python3.11/site-packages/keras_tuner/engine/tuner.py\", line 287, in run_trial\n    obj_value = self._build_and_fit_model(trial, *args, **copied_kwargs)\n                ^^^^^^^^^^^^^^^^^^^^^^^^^^^^^^^^^^^^^^^^^^^^^^^^^^^^^^^^\n  File \"/Users/aadityasurya/anaconda3/lib/python3.11/site-packages/keras_tuner/engine/tuner.py\", line 214, in _build_and_fit_model\n    results = self.hypermodel.fit(hp, model, *args, **kwargs)\n              ^^^^^^^^^^^^^^^^^^^^^^^^^^^^^^^^^^^^^^^^^^^^^^^\n  File \"/Users/aadityasurya/anaconda3/lib/python3.11/site-packages/keras_tuner/engine/hypermodel.py\", line 144, in fit\n    return model.fit(*args, **kwargs)\n           ^^^^^^^^^^^^^^^^^^^^^^^^^^\n  File \"/Users/aadityasurya/anaconda3/lib/python3.11/site-packages/keras/src/utils/traceback_utils.py\", line 70, in error_handler\n    raise e.with_traceback(filtered_tb) from None\n  File \"/var/folders/jg/nq2krdbx0_z850_vct6mrksc0000gn/T/__autograph_generated_filevyn5q8bu.py\", line 18, in tf__train_function\n    raise\nValueError: in user code:\n\n    File \"/Users/aadityasurya/anaconda3/lib/python3.11/site-packages/keras/src/engine/training.py\", line 1338, in train_function  *\n        return step_function(self, iterator)\n    File \"/Users/aadityasurya/anaconda3/lib/python3.11/site-packages/keras/src/engine/training.py\", line 1322, in step_function  **\n        outputs = model.distribute_strategy.run(run_step, args=(data,))\n    File \"/Users/aadityasurya/anaconda3/lib/python3.11/site-packages/keras/src/engine/training.py\", line 1303, in run_step  **\n        outputs = model.train_step(data)\n    File \"/Users/aadityasurya/anaconda3/lib/python3.11/site-packages/keras/src/engine/training.py\", line 1080, in train_step\n        y_pred = self(x, training=True)\n    File \"/Users/aadityasurya/anaconda3/lib/python3.11/site-packages/keras/src/utils/traceback_utils.py\", line 70, in error_handler\n        raise e.with_traceback(filtered_tb) from None\n    File \"/Users/aadityasurya/anaconda3/lib/python3.11/site-packages/keras/src/engine/input_spec.py\", line 298, in assert_input_compatibility\n        raise ValueError(\n\n    ValueError: Input 0 of layer \"model\" is incompatible with the layer: expected shape=(None, 224, 224, 3), found shape=(None, 150, 150, 3)\n\n"}